Workbook

Sheet Methodology
B2: Mobile Financial App Accessibility Scorecard — Methodology
B3: A standards-based, evidence-scored framework for rating banking / fintech apps on accessibility for blind and low-vision users
B6: 1. Global standards this scorecard is built on
B7: • WCAG 2.2 (W3C, Oct 2023) — the internationally recognised benchmark for digital accessibility. WCAG 2.0 is also formally an ISO standard (ISO/IEC 40500:2012). Level AA is the conformance target referenced by almost every accessibility law worldwide (EU EN 301 549, US Section 508, Canada's AODA, UK Equality Act guidance, Kenya's ICT Accessibility Standards, etc.).
B8: • WCAG2ICT (W3C Group Note, updated Oct 2024 for WCAG 2.1/2.2, and Aug 2025 to add Level AAA) — this is applied directly, criterion by criterion, in the 'WCAG2ICT interpretation' column of each app tab. It tells you how to reinterpret a web-authored success criterion for native software: 'web page' becomes 'software' or 'screen/view', 'keyboard' becomes 'keyboard interface' (explicitly including platform assistive technologies such as Switch Access, not only a physical keyboard), and 'programmatically determined' becomes 'exposed via the platform's accessibility API' (Android AccessibilityNodeInfo / iOS UIAccessibility) — which is exactly what Google Accessibility Scanner is testing when it flags a missing label.
B9: • Criteria WCAG2ICT-based regulation excludes for non-web software — this scorecard follows Section 508 and EN 301 549, which both state that 2.4.1 Bypass Blocks, 2.4.5 Multiple Ways, 3.2.3 Consistent Navigation and 3.2.4 Consistent Identification do not apply to non-web software (EN 301 549 additionally excludes 2.4.2 Page Titled and 3.1.2 Language of Parts). The first three are simply not included in the checklist. 3.2.4 is kept as a visible 'N/A' row rather than silently dropped, so it's clear the exclusion was a deliberate, sourced decision and not an oversight.
B10: • Platform accessibility guidelines — Android Accessibility Developer Checklist (48x48dp minimum touch target) and Apple Human Interface Guidelines (44x44pt), used alongside WCAG's own (lower) 24x24px minimum, since these are the practical benchmarks app developers are actually held to.
B11: • VPAT / EN 301 549 style reporting — the scoring table below follows the same logic used in a Voluntary Product Accessibility Template: each criterion is rated against evidence, not opinion, so the result is defensible and auditable by a third party.
B12: • Functional relevance weighting — because this research is specifically about blind and low-vision users (not accessibility in general), each criterion also carries a 'Relevance weight' reflecting how much that specific criterion affects a screen-reader-dependent user, following the 'Functional Performance' approach used in EN 301 549 and Section 508.
B14: 2. Why these specific success criteria were selected
B15: WCAG 2.2 has 87 success criteria in total. This scorecard does not use all of them, and the selection was not arbitrary — it follows a explicit filter, applied in this order:
B16: Step 1 — Start from the full WCAG 2.2 set (32 Level A, 24 Level AA, 31 Level AAA).
... B67: Known limitations of Steps 2-3. The visual review can misread small text (e.g. 'RWF' read as 'RWE'). Screens captured mid-animation or behind a keyboard produce spurious contrast results (e.g. 1.01:1), which are called out as artefacts in the Notes. Hybrid / WebView apps (e.g. Fidelity) defeat the scanner's label checks entirely, so a zero label count there means 'not evaluable', not 'pass'. Screenshots contain personal data (names, account numbers, BVN) and must be redacted before being shared or published.

Sheet Comparison Dashboard
A1: Cross-App Accessibility Comparison — Digital Financial Inclusion for Blind Users
A2: Each row pulls its numbers live from that app's own scorecard tab. Add a row and duplicate 'App Template' to score another app.
A4: App / Bank | B4: WCAG Score (0-100) | C4: Rating band | D4: WCAG Level A conformance | E4: WCAG Level AA conformance | F4: Transaction Accessibility Score | G4: Criteria Failed (WCAG) | H4: Needs manual audit (WCAG + txn) | I4: Notes
A5: BK Mobile (Bank of Kigali, Rwanda) | B5: ='BK Mobile'!$E$44 | C5: ='BK Mobile'!$E$49 | D5: ='BK Mobile'!$E$45 | E5: ='BK Mobile'!$E$46 | F5: ='BK Mobile - Transactions'!$D$21 | G5: ='BK Mobile'!$E$47 | H5: ='BK Mobile'!$E$48+'BK Mobile - Transactions'!$D$22 | I5: Scored from 2 Google Accessibility Scanner sessions, 50 screens, 17 Sep 2026. See 'BK Mobile' and 'BK Mobile - Transactions' tabs for evidence.
A6: Equity Mobile (Equity Bank, Rwanda) | B6: ='Equity Mobile RW'!$E$44 | C6: ='Equity Mobile RW'!$E$49 | D6: ='Equity Mobile RW'!$E$45 | E6: ='Equity Mobile RW'!$E$46 | F6: ='Equity Mobile RW - Transactions'!$D$21 | G6: ='Equity Mobile RW'!$E$47 | H6: ='Equity Mobile RW'!$E$48+'Equity Mobile RW - Transactions'!$D$22 | I6: Scored from 1 Google Accessibility Scanner session, 24 screens, 25 Sep 2026 (login, home, accounts, Transact hub, own-account / other-bank / e-Kash / airtime forms). No confirm or success screen was captured, so 3.3.4 and T1 are untested. Dark theme throughout.
A7: Fidelity Mobile (Fidelity Bank, Nigeria) | B7: ='Fidelity NG'!$E$44 | C7: ='Fidelity NG'!$E$49 | D7: ='Fidelity NG'!$E$45 | E7: ='Fidelity NG'!$E$46 | F7: ='Fidelity NG - Transactions'!$D$21 | G7: ='Fidelity NG'!$E$47 | H7: ='Fidelity NG'!$E$48+'Fidelity NG - Transactions'!$D$22 | I7: Scored from 1 Google Accessibility Scanner session, 40 screens, 25 Sep 2026. The app is a hybrid WebView: every finding is 'web content', and the scanner returned 0 label findings even though icon-only controls are visible. 1.1.1, 2.4.4, 2.5.3 and 4.1.2 are therefore Not Tested, which inflates this score relative to native apps. Needs a manual TalkBack audit before comparing.
A8: GTWorld (Guaranty Trust Bank, Nigeria) | B8: ='GTWorld NG'!$E$44 | C8: ='GTWorld NG'!$E$49 | D8: ='GTWorld NG'!$E$45 | E8: ='GTWorld NG'!$E$46 | F8: ='GTWorld NG - Transactions'!$D$21 | G8: ='GTWorld NG'!$E$47 | H8: ='GTWorld NG'!$E$48+'GTWorld NG - Transactions'!$D$22 | I8: Scored from 3 Google Accessibility Scanner sessions, 33 screens, 25 Sep 2026 (home, beneficiary search, transfer form, airtime purchase to success, transaction history, filters). No login screen was captured, so 3.3.7, 3.3.8 and T7 are untested. Dark theme throughout.
A9: AccessMore (Access Bank, Nigeria) | B9: ='AccessMore NG'!$E$44 | C9: ='AccessMore NG'!$E$49 | D9: ='AccessMore NG'!$E$45 | E9: ='AccessMore NG'!$E$46 | F9: ='AccessMore NG - Transactions'!$D$21 | G9: ='AccessMore NG'!$E$47 | H9: ='AccessMore NG'!$E$48+'AccessMore NG - Transactions'!$D$22 | I9: Scored from 2 Google Accessibility Scanner sessions, 21 screens, 25 Sep 2026 (home, Access / other-bank transfer, success, history, support, menu, cards, profile). The app auto-logged in, so no login screen was captured; biometric login was confirmed from Settings. Debit Cards never finished loading (S2-14 to 16).
A11: Comparability caveat: scores reflect only the screens each scan captured, and differ in coverage (e.g. no login screen for GTWorld / AccessMore; no confirm step for Equity / Fidelity). Fidelity's WebView defeated automated label checks, so its WCAG score excludes 1.1.1 / 2.4.4 / 2.5.3 / 4.1.2 and is not directly comparable until manually audited.

Sheet SC Glossary
A1: Success Criteria Glossary — Name and Plain-Language Explanation
A2: Every WCAG 2.2 success criterion used on the app scorecards, in plain language, plus why it matters specifically for a blind screen-reader user in a financial app. The three greyed-out rows at the end are success criteria that exist in WCAG but are excluded from scoring for non-web software (see Methodology, Section 1).
A4: SC # | B4: Name | C4: Level | D4: Principle | E4: Plain-language explanation | F4: Why it matters for a blind user in a financial app | G4: In this scorecard?
A5: 1.1.1 | B5: Non-text Content | C5: A | D5: Perceivable | E5: Every image, icon, or button that isn't text has a text alternative that serves the same purpose, so software can present it as text. | F5: Without this, a screen reader announces an icon-only button as just 'button' — the user has no way to know what it does. | G5: Included
A6: 1.3.1 | B6: Info and Relationships | C6: A | D6: Perceivable | E6: Structure and grouping that a sighted user perceives visually (headings, lists, related fields) must also be available programmatically, not just through layout. | F6: A screen reader can only announce structure it can detect in the accessibility tree — visual grouping alone (e.g. a box drawn around related fields) says nothing to it. | G6: Included
A7: 1.3.2 | B7: Meaningful Sequence | C7: A | D7: Perceivable | E7: When the order content is presented in affects its meaning, the correct reading order can be determined programmatically. | F7: If the swipe order jumps around the screen instead of following a logical path, a transaction form becomes very hard to fill in blind. | G7: Included
A8: 1.3.3 | B8: Sensory Characteristics | C8: A | D8: Perceivable | E8: Instructions don't rely only on shape, size, visual position, orientation, or sound to identify something (e.g. 'the round green button on the right'). | F8: A blind user cannot act on 'the button on the right' — instructions and identifiers need to work without sight. | G8: Included
A9: 1.4.1 | B9: Use of Color | C9: A | D9: Perceivable | E9: Colour is never the only way information, an action, or a state is conveyed. | F9: Directly a low-vision/colour-blind concern more than a total-blindness one, but state changes (e.g. selected vs. not) still need a non-colour cue for consistency across assistive tech. | G9: Included
A10: 2.1.1 | B10: Keyboard (assistive-tech equivalent) | C10: A | D10: Operable | E10: All functionality can be operated without requiring fine motor pointer control — via a keyboard interface, which on mobile includes assistive input methods like Switch Access. | F10: Some blind users pair external keyboards or switch devices with their phone instead of touch gestures; every action must remain reachable that way. | G10: Included
A11: 2.4.3 | B11: Focus Order | C11: A | D11: Operable | E11: Moving through interactive elements happens in an order that still makes sense and preserves how the interface operates. | F11: TalkBack/VoiceOver users navigate item-by-item; if focus order is scrambled, a form's fields may be announced out of a sensible sequence. | G11: Included
A12: 2.4.4 | B12: Link Purpose (In Context) | C12: A | D12: Operable | E12: The purpose of a link or actionable control can be understood from its own text, or its text plus surrounding context — not just 'click here'. | F12: An icon-only quick-link with no purpose text is the mobile equivalent of a 'click here' link — the destination is a guess. | G12: Included
A13: 2.5.1 | B13: Pointer Gestures | C13: A | D13: Operable | E13: Anything operated with a multi-finger or path-based gesture (e.g. a swipe pattern) can also be done with a single simple tap, unless the multi-point gesture is essential. | F13: Screen-reader users navigate with reserved swipe gestures of their own; app gestures that conflict with those, or demand precise paths, can lock a feature out entirely. | G13: Included
A14: 2.5.2 | B14: Pointer Cancellation | C14: A | D14: Operable | E14: A function doesn't trigger the instant your finger touches the screen (the 'down' event) — it triggers on release, and can be dragged off to cancel. | F14: This gives a user who mis-taps (common when exploring by touch without sight) a chance to back out before an action fires. | G14: Included
A15: 2.5.3 | B15: Label in Name | C15: A | D15: Operable | E15: If a control shows visible text, that same text is included in its accessible/programmatic name. | F15: Voice-control users (a common assistive method some blind users layer with a screen reader) say the visible label to activate a control; mismatched names break that. | G15: Included
... A44: 3.1.2 | B44: Language of Parts | C44: AA | D44: Understandable | E44: The human language of each passage or phrase can be programmatically determined, when it differs from the software's default language. | F44: EN 301 549 excludes this for non-web software. Worth a manual look regardless in a multilingual context (e.g. English UI with Kinyarwanda biller names), even though it isn't scored here. | G44: Excluded - non-web software (EN 301 549 only)

Sheet BK Mobile
A1: Accessibility Scorecard — BK Mobile
A2: Blue cells are inputs (Status / Evidence count / Notes). WCAG2ICT and Recommended Improvement columns are reference-only. Everything else recalculates automatically.
A4: SC # | B4: Success Criterion | C4: Level | D4: Principle | E4: Relevance weight (1-3) | F4: Status | G4: Status score | H4: Notes / Evidence | I4: Instances found | J4: Weighted score | K4: WCAG2ICT interpretation (native/mobile software) | L4: Tested? | M4: Recommended Improvement
A5: 1.1.1 | B5: Non-text Content | C5: A | D5: Perceivable | E5: 3 | F5: Fail | G5: =IF(F5="Pass",1,IF(F5="Partial",0.5,IF(F5="Fail",0,0))) | H5: 146 unlabelled controls + 47 visible text strings not exposed to a screen reader, across nearly all screens. | I5: 193 | J5: =E5*G5 | K5: 'Web page' -> 'software'; a non-text control's accessible name must be exposed via the platform accessibility API (Android AccessibilityNodeInfo / iOS UIAccessibility), not just visible on screen. | L5: =IF(OR(F5="Pass",F5="Partial",F5="Fail"),1,0) | M5: Add a contentDescription (Android) / accessibilityLabel (iOS) to every icon-only control flagged (146 instances) - start with the 8 home-screen quick-links, back arrow, notification bell, and hide-balance icon. Separately, re-implement the 47 unexposed text strings (biller categories, 'Set target', validation messages) as real accessible text nodes rather than custom-drawn or image-based text.
A6: 1.3.1 | B6: Info and Relationships | C6: A | D6: Perceivable | E6: 2 | F6: Partial | G6: =IF(F6="Pass",1,IF(F6="Partial",0.5,IF(F6="Fail",0,0))) | H6: Overlapping clickable container on home screen breaks visual/structural grouping; touch-target boundaries misaligned with visual rows on Pay > Billers. | I6: 8 | J6: =E6*G6 | K6: 'Markup' -> structural relationships conveyed through the accessibility tree (grouping, headings, lists) rather than HTML; a screen reader must be able to derive the same grouping a sighted user sees. | L6: =IF(OR(F6="Pass",F6="Partial",F6="Fail"),1,0) | M6: Break the single large clickable container on the home screen into separately focusable, properly grouped elements (account card, quick-links grid, promo banner). Separately, re-align the Pay > Billers list's touch/focus boundaries so each row's hit area matches its visible row exactly.
A7: 1.3.2 | B7: Meaningful Sequence | C7: A | D7: Perceivable | E7: 2 | F7: Not Tested | G7: =IF(F7="Pass",1,IF(F7="Partial",0.5,IF(F7="Fail",0,0))) | H7: Requires manual TalkBack swipe-order testing. | I7: - | J7: =E7*G7 | K7: Applies as written: the swipe/focus order exposed to a screen reader must match the meaningful reading order, independent of visual layout. | L7: =IF(OR(F7="Pass",F7="Partial",F7="Fail"),1,0) | M7: No fix to prescribe yet - conduct the manual test first to confirm actual status.
A8: 1.3.3 | B8: Sensory Characteristics | C8: A | D8: Perceivable | E8: 1 | F8: Pass | G8: =IF(F8="Pass",1,IF(F8="Partial",0.5,IF(F8="Fail",0,0))) | H8: Network selector (MTN/Airtel) uses icon + colour + text label, not colour alone. | I8: - | J8: =E8*G8 | K8: Applies as written; no web-specific terms to reinterpret. | L8: =IF(OR(F8="Pass",F8="Partial",F8="Fail"),1,0) | M8: No action needed on current evidence.
A9: 1.4.1 | B9: Use of Color | C9: A | D9: Perceivable | E9: 1 | F9: Partial | G9: =IF(F9="Pass",1,IF(F9="Partial",0.5,IF(F9="Fail",0,0))) | H9: Show/hide-balance control relies on an eye icon only, with no text state indicator. | I9: 1 | J9: =E9*G9 | K9: Applies as written; on native software this covers icon-only state indicators as much as web colour cues. | L9: =IF(OR(F9="Pass",F9="Partial",F9="Fail"),1,0) | M9: Add a text or announced state alongside the eye icon for show/hide balance (e.g. 'Balance hidden' / 'Balance visible'), so the state isn't conveyed by icon shape alone.
A10: 2.1.1 | B10: Keyboard / assistive-tech equivalent | C10: A | D10: Operable | E10: 2 | F10: Not Tested | G10: =IF(F10="Pass",1,IF(F10="Partial",0.5,IF(F10="Fail",0,0))) | H10: Requires manual Switch Access / external keyboard testing. | I10: - | J10: =E10*G10 | K10: 'Keyboard' -> 'keyboard interface', which WCAG2ICT clarifies includes assistive technologies such as Switch Access/Full Keyboard Access that emulate key input, not only a physical keyboard. | L10: =IF(OR(F10="Pass",F10="Partial",F10="Fail"),1,0) | M10: No fix to prescribe yet - conduct the manual test first to confirm actual status.
A11: 2.4.3 | B11: Focus Order | C11: A | D11: Operable | E11: 3 | F11: Not Tested | G11: =IF(F11="Pass",1,IF(F11="Partial",0.5,IF(F11="Fail",0,0))) | H11: Requires manual TalkBack testing. | I11: - | J11: =E11*G11 | K11: Applies as written to the platform's own focus/accessibility-cursor order. | L11: =IF(OR(F11="Pass",F11="Partial",F11="Fail"),1,0) | M11: No fix to prescribe yet - conduct the manual test first to confirm actual status.
A12: 2.4.4 | B12: Link Purpose (In Context) | C12: A | D12: Operable | E12: 2 | F12: Fail | G12: =IF(F12="Pass",1,IF(F12="Partial",0.5,IF(F12="Fail",0,0))) | H12: Icon-only quick links / nav items with no accessible purpose text (e.g. Statement, Electricity, Get Loan icons). | I12: 146 | J12: =E12*G12 | K12: 'Link' -> any control that navigates or triggers an action (a quick-link icon, a list row); purpose must be determinable from its accessible name or surrounding context. | L12: =IF(OR(F12="Pass",F12="Partial",F12="Fail"),1,0) | M12: Give every quick-link/nav icon an accessible name that states its destination or action in words (e.g. 'View statement', not just a document icon), so purpose is announced without the user having to guess and activate it to find out.
A13: 2.5.1 | B13: Pointer Gestures | C13: A | D13: Operable | E13: 1 | F13: Pass | G13: =IF(F13="Pass",1,IF(F13="Partial",0.5,IF(F13="Fail",0,0))) | H13: No multi-point or path-based gestures observed in the flows captured. | I13: - | J13: =E13*G13 | K13: Applies as written; written with touch interfaces in mind from WCAG 2.1 onward. | L13: =IF(OR(F13="Pass",F13="Partial",F13="Fail"),1,0) | M13: No action needed on current evidence.
A14: 2.5.2 | B14: Pointer Cancellation | C14: A | D14: Operable | E14: 1 | F14: Not Tested | G14: =IF(F14="Pass",1,IF(F14="Partial",0.5,IF(F14="Fail",0,0))) | H14: Requires manual down-event/up-event testing. | I14: - | J14: =E14*G14 | K14: Applies as written to native touch handling (down-event vs up-event activation). | L14: =IF(OR(F14="Pass",F14="Partial",F14="Fail"),1,0) | M14: No fix to prescribe yet - conduct the manual test first to confirm actual status.
A15: 2.5.3 | B15: Label in Name | C15: A | D15: Operable | E15: 2 | F15: Partial | G15: =IF(F15="Pass",1,IF(F15="Partial",0.5,IF(F15="Fail",0,0))) | H15: Visible text (e.g. 'Savings', biller category names) not confirmed to match or exist in the accessible name. | I15: 47 | J15: =E15*G15 | K15: Applies as written: the programmatic accessible name must contain the visible label text so voice-control users can reference what they see. | L15: =IF(OR(F15="Pass",F15="Partial",F15="Fail"),1,0) | M15: Audit controls such as 'Savings' and each biller category row to confirm their accessible name contains the visible label text verbatim, so voice-control users referencing what they see can activate them.
A16: 3.3.1 | B16: Error Identification | C16: A | D16: Understandable | E16: 3 | F16: Fail | G16: =IF(F16="Pass",1,IF(F16="Partial",0.5,IF(F16="Fail",0,0))) | H16: Mobile-number validation message detected as visible text not confirmed announced to a screen reader. | I16: 1 | J16: =E16*G16 | K16: Applies as written; the error must be identified through the accessibility API (e.g. announced), not only shown visually. | L16: =IF(OR(F16="Pass",F16="Partial",F16="Fail"),1,0) | M16: Expose the mobile-number-length validation message as a live-region announcement (Android accessibility event / iOS UIAccessibility postNotification) so it is spoken immediately when it appears, not only shown as visual red text.
A17: 3.3.2 | B17: Labels or Instructions | C17: A | D17: Understandable | E17: 3 | F17: Fail | G17: =IF(F17="Pass",1,IF(F17="Partial",0.5,IF(F17="Fail",0,0))) | H17: Form fields (Phone number, Account holder) rely on placeholder text with no confirmed persistent accessible label. | I17: 3 | J17: =E17*G17 | K17: Applies as written; WCAG2ICT notes placeholder-only text that disappears on input/focus is a common native-software failure mode of this criterion. | L17: =IF(OR(F17="Pass",F17="Partial",F17="Fail"),1,0) | M17: Replace placeholder-only field labels ('Phone number', 'Account holder') with a persistent label that stays visible and accessible after the user starts typing (e.g. a floating-label pattern), so the field's purpose isn't lost once input begins.
A18: 3.3.9 | B18: Redundant Entry | C18: A | D18: Understandable | E18: 1 | F18: Not Tested | G18: =IF(F18="Pass",1,IF(F18="Partial",0.5,IF(F18="Fail",0,0))) | H18: Requires manual review of multi-step forms (e.g. transfer flows). | I18: - | J18: =E18*G18 | K18: Applies as written; added in WCAG 2.2 with no web-specific terms. | L18: =IF(OR(F18="Pass",F18="Partial",F18="Fail"),1,0) | M18: No fix to prescribe yet - conduct the manual test first to confirm actual status.
A19: 1.3.5 | B19: Identify Input Purpose | C19: AA | D19: Perceivable | E19: 2 | F19: Not Tested | G19: =IF(F19="Pass",1,IF(F19="Partial",0.5,IF(F19="Fail",0,0))) | H19: Requires manual check: do fields like phone number / amount expose a standard input type so OS-level autofill can offer to complete them? | I19: - | J19: =E19*G19 | K19: 'Input purpose... can be programmatically determined' maps to using standard platform input types/autofill hints (e.g. Android autofillHints) rather than a generic text field. | L19: =IF(OR(F19="Pass",F19="Partial",F19="Fail"),1,0) | M19: No fix to prescribe yet - conduct the manual test first to confirm actual status.
A20: 3.2.1 | B20: On Focus | C20: A | D20: Operable | E20: 2 | F20: Not Tested | G20: =IF(F20="Pass",1,IF(F20="Partial",0.5,IF(F20="Fail",0,0))) | H20: Requires manual check: does simply moving focus onto a field (without activating it) ever trigger a navigation or submission? | I20: - | J20: =E20*G20 | K20: Applies as written; on native software this covers focus changes triggered by the accessibility cursor, not only literal keyboard focus. | L20: =IF(OR(F20="Pass",F20="Partial",F20="Fail"),1,0) | M20: No fix to prescribe yet - conduct the manual test first to confirm actual status.
A21: 3.2.2 | B21: On Input | C21: A | D21: Operable | E21: 2 | F21: Not Tested | G21: =IF(F21="Pass",1,IF(F21="Partial",0.5,IF(F21="Fail",0,0))) | H21: Requires manual check: does changing a field's value (e.g. selecting MTN vs Airtel) ever submit or navigate without an explicit confirm action? | I21: - | J21: =E21*G21 | K21: Applies as written; important on forms with toggles/selectors (network, Self/Other) that a screen-reader user changes one at a time. | L21: =IF(OR(F21="Pass",F21="Partial",F21="Fail"),1,0) | M21: No fix to prescribe yet - conduct the manual test first to confirm actual status.
A22: 4.1.2 | B22: Name, Role, Value | C22: A | D22: Robust | E22: 3 | F22: Fail | G22: =IF(F22="Pass",1,IF(F22="Partial",0.5,IF(F22="Fail",0,0))) | H22: 146 controls with no accessible name, plus 8 overlapping/duplicate clickable regions that confuse role and identity. | I22: 154 | J22: =E22*G22 | K22: This is the core native-software criterion in WCAG2ICT: 'name, role, value' maps directly to what a platform accessibility API exposes for each control - exactly what Google Accessibility Scanner tests. | L22: =IF(OR(F22="Pass",F22="Partial",F22="Fail"),1,0) | M22: Run a full pass of every custom control against the platform accessibility API to confirm name, role and state are all exposed. Separately, fix the overlapping clickable container on the home screen so the account card, quick-links grid and promo banner are distinct, correctly bounded touch/accessibility targets instead of one large parent overlapping its children.
A23: 1.4.3 | B23: Contrast (Minimum) | C23: AA | D23: Perceivable | E23: 1 | F23: Fail | G23: =IF(F23="Pass",1,IF(F23="Partial",0.5,IF(F23="Fail",0,0))) | H23: Text contrast as low as 1.06:1 and 1.11:1 measured, against a 4.5:1 requirement. | I23: 4 | J23: =E23*G23 | K23: Applies as written; 'text' includes native UI labels, not only web text. | L23: =IF(OR(F23="Pass",F23="Partial",F23="Fail"),1,0) | M23: Raise the specific text instances measured at 1.06:1 and 1.11:1 to at least 4.5:1. This looks like a dark-theme regression (a disabled/loading text style never updated for dark mode) rather than an isolated typo - check that style across the app, not just the flagged instances.
A24: 1.4.4 | B24: Resize Text | C24: AA | D24: Perceivable | E24: 1 | F24: Not Tested | G24: =IF(F24="Pass",1,IF(F24="Partial",0.5,IF(F24="Fail",0,0))) | H24: Requires manual OS font-scaling test. | I24: - | J24: =E24*G24 | K24: Applies with a platform-specific mechanism: resizing happens via the OS text-scale setting rather than browser zoom. | L24: =IF(OR(F24="Pass",F24="Partial",F24="Fail"),1,0) | M24: No fix to prescribe yet - conduct the manual test first to confirm actual status.
A25: 1.4.10 | B25: Reflow | C25: AA | D25: Perceivable | E25: 1 | F25: Not Tested | G25: =IF(F25="Pass",1,IF(F25="Partial",0.5,IF(F25="Fail",0,0))) | H25: Requires manual OS font-scaling / zoom test. | I25: - | J25: =E25*G25 | K25: WCAG2ICT notes this applies where the software supports resizing/zoom; if the app has no zoom/scale feature at all, evaluate against the OS-level scaling it does support. | L25: =IF(OR(F25="Pass",F25="Partial",F25="Fail"),1,0) | M25: No fix to prescribe yet - conduct the manual test first to confirm actual status.
A26: 1.4.11 | B26: Non-text Contrast | C26: AA | D26: Perceivable | E26: 2 | F26: Fail | G26: =IF(F26="Pass",1,IF(F26="Partial",0.5,IF(F26="Fail",0,0))) | H26: Recurring ~2.74:1 icon contrast (bottom navigation, quick links) against a 3.0:1 minimum. | I26: 131 | J26: =E26*G26 | K26: Applies as written to native icons and UI component boundaries. | L26: =IF(OR(F26="Pass",F26="Partial",F26="Fail"),1,0) | M26: Change the recurring icon colour pair (~#566273 on #161D26, 2.74:1), used across the bottom navigation and quick-link icons, to a combination reaching at least 3.0:1 - e.g. lighten the icon foreground colour.
A27: 2.4.6 | B27: Headings and Labels | C27: AA | D27: Operable | E27: 1 | F27: Pass | G27: =IF(F27="Pass",1,IF(F27="Partial",0.5,IF(F27="Fail",0,0))) | H27: Screen titles are present and descriptive (Mobile money, Confirm transfer, Savings, Pay). | I27: - | J27: =E27*G27 | K27: 'Web page' -> 'screen/view'; each screen and section needs a descriptive, programmatically exposed title/heading. | L27: =IF(OR(F27="Pass",F27="Partial",F27="Fail"),1,0) | M27: No action needed on current evidence.
A28: 2.4.7 | B28: Focus Visible | C28: AA | D28: Operable | E28: 1 | F28: Not Tested | G28: =IF(F28="Pass",1,IF(F28="Partial",0.5,IF(F28="Fail",0,0))) | H28: Requires manual keyboard/switch focus-indicator testing. | I28: - | J28: =E28*G28 | K28: Applies where the platform supports a visible focus indicator (external keyboard, Switch Access, D-pad); not exercised by pure touch/screen-reader use, so needs manual testing on the relevant input mode. | L28: =IF(OR(F28="Pass",F28="Partial",F28="Fail"),1,0) | M28: No fix to prescribe yet - conduct the manual test first to confirm actual status.
A29: 2.5.8 | B29: Target Size (Minimum, 24x24px) | C29: AA | D29: Operable | E29: 2 | F29: Partial | G29: =IF(F29="Pass",1,IF(F29="Partial",0.5,IF(F29="Fail",0,0))) | H29: Most flagged targets (32-41dp) clear WCAG's 24px floor, but several (24-26dp height) do not. | I29: 246 | J29: =E29*G29 | K29: Applies as written to native touch targets; note platform guidance (Android 48dp, Apple 44pt) is stricter than WCAG's own 24px floor - both are reported here. | L29: =IF(OR(F29="Pass",F29="Partial",F29="Fail"),1,0) | M29: Increase the specific undersized targets (24-26dp height items, e.g. the back button and hide-balance icon) to clear the WCAG 24px floor, and ideally Android's 48dp guideline.
A30: 3.2.4 | B30: Consistent Identification | C30: AA | D30: Understandable | E30: 0 | F30: N/A | G30: =IF(F30="Pass",1,IF(F30="Partial",0.5,IF(F30="Fail",0,0))) | H30: Excluded per Section 508 and EN 301 549, which both state (building on WCAG2ICT) that this criterion does not apply to non-web software. Retained here as a visible N/A rather than silently dropped. | I30: - | J30: =E30*G30 | K30: Explicitly excluded for non-web software by Section 508 and EN 301 549 - not scored. | L30: =IF(OR(F30="Pass",F30="Partial",F30="Fail"),1,0) | M30: Not applicable - excluded for non-web software.
A31: 3.3.3 | B31: Error Suggestion | C31: AA | D31: Understandable | E31: 1 | F31: Not Tested | G31: =IF(F31="Pass",1,IF(F31="Partial",0.5,IF(F31="Fail",0,0))) | H31: Requires manual review of validation-message wording and exposure. | I31: - | J31: =E31*G31 | K31: Applies as written. | L31: =IF(OR(F31="Pass",F31="Partial",F31="Fail"),1,0) | M31: No fix to prescribe yet - conduct the manual test first to confirm actual status.
A32: 3.3.4 | B32: Error Prevention (Legal, Financial, Data) | C32: AA | D32: Understandable | E32: 3 | F32: Partial | G32: =IF(F32="Pass",1,IF(F32="Partial",0.5,IF(F32="Fail",0,0))) | H32: A Confirm-Transfer review step exists, but its fields are not confirmed screen-reader accessible - undermining the safeguard for blind users specifically. | I32: - | J32: =E32*G32 | K32: Applies as written and is squarely about transactions ('legal commitments, financial transactions'); directly relevant to this app's core function. | L32: =IF(OR(F32="Pass",F32="Partial",F32="Fail"),1,0) | M32: Fix the underlying labelling of the Confirm Transfer screen (see 4.1.2 / 3.3.2 above) so the review-before-send safeguard that already exists visually actually functions for a screen-reader user, not only a sighted one.
A33: 3.3.7 | B33: Accessible Authentication (Minimum) | C33: AA | D33: Understandable | E33: 3 | F33: Fail | G33: =IF(F33="Pass",1,IF(F33="Partial",0.5,IF(F33="Fail",0,0))) | H33: PIN-only login via an on-screen numeric pad; no evidence of a non-visually-broadcast or biometric-first alternative. | I33: - | J33: =E33*G33 | K33: Applies as written; added in WCAG 2.2 with no web-specific terms to reinterpret. | L33: =IF(OR(F33="Pass",F33="Partial",F33="Fail"),1,0) | M33: Offer biometric login (fingerprint/face) as the primary sign-in method, with a screen-reader-safe fallback (e.g. a PIN pad where entry is not spoken aloud digit-by-digit, or a headphone-routed confirmation) rather than a passcode pad that always broadcasts each digit.
A34: 4.1.3 | B34: Status Messages | C34: AA | D34: Robust | E34: 3 | F34: Not Tested | G34: =IF(F34="Pass",1,IF(F34="Partial",0.5,IF(F34="Fail",0,0))) | H34: Requires manual testing of transaction success/failure toast announcements. | I34: - | J34: =E34*G34 | K34: 'Programmatically determined through role or properties' -> exposed via the accessibility API's live-region/announcement mechanism (e.g. Android AccessibilityEvent) so a status change is spoken without moving focus. | L34: =IF(OR(F34="Pass",F34="Partial",F34="Fail"),1,0) | M34: No fix to prescribe yet - conduct the manual test first to confirm actual status.
A35: 2.2.1 | B35: Timing Adjustable | C35: A | D35: Operable | E35: 3 | F35: Not Tested | G35: =IF(F35="Pass",1,IF(F35="Partial",0.5,IF(F35="Fail",0,0))) | H35: Requires manual test: can a screen-reader user extend/disable any time limit on OTP entry, session timeout, or transfer confirmation? | I35: - | J35: =E35*G35 | K35: Applies as written; particularly relevant to native software session timeouts and OTP countdown timers. | L35: =IF(OR(F35="Pass",F35="Partial",F35="Fail"),1,0) | M35: No fix to prescribe yet - conduct the manual test first to confirm actual status.
A36: 2.2.6 | B36: Timeouts (warn of data loss) | C36: AAA | D36: Operable | E36: 1 | F36: Not Tested | G36: =IF(F36="Pass",1,IF(F36="Partial",0.5,IF(F36="Fail",0,0))) | H36: Requires manual test: is the user warned before a timed-out session discards an in-progress transaction? | I36: - | J36: =E36*G36 | K36: Applies as written. | L36: =IF(OR(F36="Pass",F36="Partial",F36="Fail"),1,0) | M36: No fix to prescribe yet - conduct the manual test first to confirm actual status.
A37: 2.5.5 | B37: Target Size (Enhanced, 44x44px) | C37: AAA | D37: Operable | E37: 1 | F37: Fail | G37: =IF(F37="Pass",1,IF(F37="Partial",0.5,IF(F37="Fail",0,0))) | H37: The majority of flagged targets (32-41dp) fall below the 44px enhanced minimum. | I37: 246 | J37: =E37*G37 | K37: Applies as written to native touch targets. | L37: =IF(OR(F37="Pass",F37="Partial",F37="Fail"),1,0) | M37: Where feasible, increase touch targets to at least 44x44px (ideally Android's 48dp) - prioritise the back arrow, hide-balance icon and quick-link icons, which are the most frequently used controls in the app.
A38: 3.3.6 | B38: Error Prevention (All) | C38: AAA | D38: Understandable | E38: 1 | F38: Not Tested | G38: =IF(F38="Pass",1,IF(F38="Partial",0.5,IF(F38="Fail",0,0))) | H38: Requires manual review across all transactional flows. | I38: - | J38: =E38*G38 | K38: Applies as written. | L38: =IF(OR(F38="Pass",F38="Partial",F38="Fail"),1,0) | M38: No fix to prescribe yet - conduct the manual test first to confirm actual status.
A39: 3.3.8 | B39: Accessible Authentication (Enhanced) | C39: AAA | D39: Understandable | E39: 1 | F39: Fail | G39: =IF(F39="Pass",1,IF(F39="Partial",0.5,IF(F39="Fail",0,0))) | H39: No cognitive-function-test-free login alternative confirmed. | I39: - | J39: =E39*G39 | K39: Applies as written; added in WCAG 2.2. | L39: =IF(OR(F39="Pass",F39="Partial",F39="Fail"),1,0) | M39: As the enhanced version of the 3.3.7 fix: remove the cognitive-function-test requirement from routine sign-in entirely where possible, reserving PIN entry for account recovery only once biometric login is the default path.
A41: SCORE SUMMARY
A42: Weighted score achieved (sum) | E42: =SUM(J5:J39)
...

Sheet BK Mobile - Transactions
A1: Financial Transaction Accessibility (Supplemental) BK Mobile
A2: Not part of WCAG. Grounded in GSMA Mobile Money Accessibility Guidelines, ITU-T F.921, and EN 301 549's authentication / real-time-transaction clauses. Blue cells are inputs.
A4: Ref | B4: Check | C4: Standard reference | D4: Weight (1-3) | E4: Status | F4: Status score | G4: Notes / Evidence | H4: Weighted score | I4: Tested? | J4: Recommended Improvement
A5: T1 | B5: Transaction confirmation screen states recipient, amount, currency and fee as one clear announced statement before an irreversible send. | C5: WCAG 3.3.4; GSMA MM Accessibility Guideline 4.2 | D5: 3 | E5: Partial | F5: =IF(E5="Pass",1,IF(E5="Partial",0.5,IF(E5="Fail",0,0))) | G5: Confirm-transfer fields exist but are flagged as generic elements, not label+value pairs (see WCAG tab, 3.3.4). | H5: =D5*F5 | I5: =IF(OR(E5="Pass",E5="Partial",E5="Fail"),1,0) | J5: Convert the Confirm-Transfer label+value rows into one coherent announced statement per field (e.g. 'Recipient: [name]'), the transaction-specific expression of the 4.1.2 / 3.3.2 fixes above.
A6: T2 | B6: Time allowed to enter an OTP/PIN or confirm a transfer can be extended, and is not so short that assistive-tech input causes failure. | C6: WCAG 2.2.1; EN 301 549 §11.7 | D6: 2 | E6: Not Tested | F6: =IF(E6="Pass",1,IF(E6="Partial",0.5,IF(E6="Fail",0,0))) | G6: Requires manual timing test with TalkBack enabled. | H6: =D6*F6 | I6: =IF(OR(E6="Pass",E6="Partial",E6="Fail"),1,0) | J6: No fix to prescribe yet - conduct the manual test first to confirm actual status.
A7: T3 | B7: Transaction success or failure is announced non-visually (spoken/haptic), not only as an on-screen toast. | C7: WCAG 4.1.3; GSMA MM Accessibility Guideline 4.4 | D7: 3 | E7: Not Tested | F7: =IF(E7="Pass",1,IF(E7="Partial",0.5,IF(E7="Fail",0,0))) | G7: Requires manual test; automated scanning cannot capture transient toast messages. | H7: =D7*F7 | I7: =IF(OR(E7="Pass",E7="Partial",E7="Fail"),1,0) | J7: No fix to prescribe yet - conduct the manual test first to confirm actual status.
A8: T4 | B8: Digital receipts / statements (SMS, email, in-app PDF) are delivered as accessible text, not a flattened image. | C8: GSMA MM Accessibility Guideline 5.1 | D8: 2 | E8: Not Tested | F8: =IF(E8="Pass",1,IF(E8="Partial",0.5,IF(E8="Fail",0,0))) | G8: Statement export (Get Statement) observed in-app; format and screen-reader compatibility not verified. | H8: =D8*F8 | I8: =IF(OR(E8="Pass",E8="Partial",E8="Fail"),1,0) | J8: No fix to prescribe yet - conduct the manual test first to confirm actual status.
A9: T5 | B9: Amounts and currency are unambiguous when read aloud (e.g. 'RWF 1,000' is not mis-announced as a date or misread digit-by-digit). | C9: ITU-T F.921 §6.3 | D9: 2 | E9: Not Tested | F9: =IF(E9="Pass",1,IF(E9="Partial",0.5,IF(E9="Fail",0,0))) | G9: Requires manual screen-reader listening test on amount fields. | H9: =D9*F9 | I9: =IF(OR(E9="Pass",E9="Partial",E9="Fail"),1,0) | J9: No fix to prescribe yet - conduct the manual test first to confirm actual status.
A10: T6 | B10: A non-touchscreen channel (USSD, IVR, or agent-assisted banking) exists for users who cannot operate a smartphone app, and that channel is itself usable non-visually. | C10: GSMA MM Accessibility Guideline 2.1; ITU-D digital financial inclusion guidance | D10: 3 | E10: Not Tested | F10: =IF(E10="Pass",1,IF(E10="Partial",0.5,IF(E10="Fail",0,0))) | G10: Out of scope for this app-only scan. Material gap for East Africa: much mobile money usage is USSD/agent-based, not app-based, and this scorecard has not evaluated that channel at all. | H10: =D10*F10 | I10: =IF(OR(E10="Pass",E10="Partial",E10="Fail"),1,0) | J10: No fix to prescribe yet - conduct the manual test first to confirm actual status.
A11: T7 | B11: Biometric login is offered as an alternative to a spoken/visible PIN. | C11: WCAG 3.3.7/3.3.8 | D11: 2 | E11: Not Tested | F11: =IF(E11="Pass",1,IF(E11="Partial",0.5,IF(E11="Fail",0,0))) | G11: Not confirmed from screenshots; login flow only showed passcode entry. | H11: =D11*F11 | I11: =IF(OR(E11="Pass",E11="Partial",E11="Fail"),1,0) | J11: No fix to prescribe yet - conduct the manual test first to confirm actual status.
A12: T8 | B12: Fraud/security alerts and a dispute or help-escalation path are reachable and readable with a screen reader. | C12: EN 301 549 §11.8; GSMA MM Accessibility Guideline 4.5 | D12: 2 | E12: Partial | F12: =IF(E12="Pass",1,IF(E12="Partial",0.5,IF(E12="Fail",0,0))) | G12: 'Email us' / 'Call us locally' links are present as visible text on the home screen; screen-reader compatibility and fraud-alert flows not verified. | H12: =D12*F12 | I12: =IF(OR(E12="Pass",E12="Partial",E12="Fail"),1,0) | J12: Confirm 'Email us' and 'Call us locally' are announced with clear accessible names and roles, and manually test that the actual fraud-alert and dispute-resolution flow behind them (not just the entry link) is screen-reader accessible end to end.
A13: T9 | B13: Transaction limits, fees and exchange rates are disclosed as accessible text before confirmation, not only visually. | C13: WCAG 3.3.4; consumer-protection disclosure norms (e.g. AFI / GSMA) | D13: 3 | E13: Partial | F13: =IF(E13="Pass",1,IF(E13="Partial",0.5,IF(E13="Fail",0,0))) | G13: A 'Transaction Fee' field is shown on Confirm Transfer, but flagged under 3.3.4/4.1.2 as not confirmed accessible. | H13: =D13*F13 | I13: =IF(OR(E13="Pass",E13="Partial",E13="Fail"),1,0) | J13: Expose the 'Transaction Fee' field, and any transaction limit or exchange-rate disclosure, as accessible text explicitly tied to its label - not a generically-labelled value a screen reader can't connect to what it represents.
A14: T10 | B14: A multi-step transaction does not require re-entering the same information (e.g. phone number typed once, reused for confirmation). | C14: WCAG 3.3.9 | D14: 1 | E14: Not Tested | F14: =IF(E14="Pass",1,IF(E14="Partial",0.5,IF(E14="Fail",0,0))) | G14: Requires manual walkthrough of the full transfer flow. | H14: =D14*F14 | I14: =IF(OR(E14="Pass",E14="Partial",E14="Fail"),1,0) | J14: No fix to prescribe yet - conduct the manual test first to confirm actual status.
A15: T11 | B15: Switching app language does not reset or lose an in-progress transaction, and the switcher itself is screen-reader accessible. | C15: WCAG 3.1.2; EN 301 549 §11.9 | D15: 1 | E15: Not Tested | F15: =IF(E15="Pass",1,IF(E15="Partial",0.5,IF(E15="Fail",0,0))) | G15: An 'EN' language selector is visible on the login screen; behaviour when switched mid-task not tested. | H15: =D15*F15 | I15: =IF(OR(E15="Pass",E15="Partial",E15="Fail"),1,0) | J15: No fix to prescribe yet - conduct the manual test first to confirm actual status.
A16: T12 | B16: An accessible-format customer support channel (toll-free voice line, etc.) is discoverable for a user who cannot complete a transaction independently. | C16: GSMA MM Accessibility Guideline 4.5 | D16: 2 | E16: Pass | F16: =IF(E16="Pass",1,IF(E16="Partial",0.5,IF(E16="Fail",0,0))) | G16: 'Email us' and 'Call us locally' are both present as plain, readable text on the home screen. | H16: =D16*F16 | I16: =IF(OR(E16="Pass",E16="Partial",E16="Fail"),1,0) | J16: No action needed on current evidence.
A18: TRANSACTION ACCESSIBILITY SCORE
A19: Weighted score achieved (sum) | D19: =SUM(H5:H16)
A20: Weighted score possible (tested only) | D20: =SUMPRODUCT(I5:I16*D5:D16)
A21: TRANSACTION SCORE (0-100) | D21: =IFERROR(D19/D20*100,0)
A22: Checks not yet tested (count) | D22: =COUNTIF(E5:E16,"Not Tested")

Sheet Equity Mobile RW
A1: Accessibility Scorecard — Equity Mobile (Equity Bank, Rwanda)
A2: Blue cells are inputs (Status / Evidence count / Notes). WCAG2ICT and Recommended Improvement columns are reference-only. Everything else recalculates automatically.
A4: SC # | B4: Success Criterion | C4: Level | D4: Principle | E4: Relevance weight (1-3) | F4: Status | G4: Status score | H4: Notes / Evidence | I4: Instances found | J4: Weighted score | K4: WCAG2ICT interpretation (native/mobile software) | L4: Tested? | M4: Recommended Improvement
A5: 1.1.1 | B5: Non-text Content | C5: A | D5: Perceivable | E5: 3 | F5: Fail | G5: =IF(F5="Pass",1,IF(F5="Partial",0.5,IF(F5="Fail",0,0))) | H5: 45 unlabelled controls + 4 visible text strings not exposed to a screen reader. The unlabelled controls are the back arrow / sheet close X on almost every screen, plus the persistent header's profile avatar, QR-scanner and notification-bell icons and the currency dropdown (screens 5-24). | I5: 49 | J5: =E5*G5 | K5: 'Web page' -> 'software'; a non-text control's accessible name must be exposed via the platform accessibility API (Android AccessibilityNodeInfo / iOS UIAccessibility), not just visible on screen. | L5: =IF(OR(F5="Pass",F5="Partial",F5="Fail"),1,0) | M5: Add a contentDescription to the back arrow and bottom-sheet close X (used on nearly every screen), and to the header's avatar, QR-scanner and notification-bell icons and the currency dropdown. Make the account-card text (account type/number, 'View', 'Currency' heading) real accessible text nodes.
A6: 1.3.1 | B6: Info and Relationships | C6: A | D6: Perceivable | E6: 2 | F6: Partial | G6: =IF(F6="Pass",1,IF(F6="Partial",0.5,IF(F6="Fail",0,0))) | H6: The bank-picker radio list exposes 6 identical 'not checked' items with no association to the bank name beside each (screen 15). Sheet titles are duplicated behind bottom sheets (15, 16). The 'Home' label is duplicated on the centre FAB (6). | I6: 3 | J6: =E6*G6 | K6: 'Markup' -> structural relationships conveyed through the accessibility tree (grouping, headings, lists) rather than HTML; a screen reader must be able to derive the same grouping a sighted user sees. | L6: =IF(OR(F6="Pass",F6="Partial",F6="Fail"),1,0) | M6: Group each radio button with its bank name so it is announced as e.g. 'Bank of Kigali, radio button, not checked'. Hide the covered page header from accessibility services while a bottom sheet is open.
A7: 1.3.2 | B7: Meaningful Sequence | C7: A | D7: Perceivable | E7: 2 | F7: Not Tested | G7: =IF(F7="Pass",1,IF(F7="Partial",0.5,IF(F7="Fail",0,0))) | H7: Requires manual TalkBack swipe-order testing. | I7: - | J7: =E7*G7 | K7: Applies as written: the swipe/focus order exposed to a screen reader must match the meaningful reading order, independent of visual layout. | L7: =IF(OR(F7="Pass",F7="Partial",F7="Fail"),1,0) | M7: No fix to prescribe yet - conduct the manual test first to confirm actual status.
A8: 1.3.3 | B8: Sensory Characteristics | C8: A | D8: Perceivable | E8: 1 | F8: Pass | G8: =IF(F8="Pass",1,IF(F8="Partial",0.5,IF(F8="Fail",0,0))) | H8: Forex 'To Buy' / 'To Sell' use colour + arrow + text. The 'selected' radio uses a checkmark shape, not colour alone (9). No shape-only or position-only instructions observed. | I8: - | J8: =E8*G8 | K8: Applies as written; no web-specific terms to reinterpret. | L8: =IF(OR(F8="Pass",F8="Partial",F8="Fail"),1,0) | M8: No action needed on current evidence.
A9: 1.4.1 | B9: Use of Color | C9: A | D9: Perceivable | E9: 1 | F9: Partial | G9: =IF(F9="Pass",1,IF(F9="Partial",0.5,IF(F9="Fail",0,0))) | H9: The selected Transact filter chip differs only by a coral outline and text colour (7, 13). Account carousel position is shown only by page dots (5, 6). | I9: 2 | J9: =E9*G9 | K9: Applies as written; on native software this covers icon-only state indicators as much as web colour cues. | L9: =IF(OR(F9="Pass",F9="Partial",F9="Fail"),1,0) | M9: Expose the selected filter chip's state (selected / not selected) programmatically and add a non-colour cue such as a checkmark or bold fill. Announce carousel position ('Account 1 of 2').
A10: 2.1.1 | B10: Keyboard / assistive-tech equivalent | C10: A | D10: Operable | E10: 2 | F10: Not Tested | G10: =IF(F10="Pass",1,IF(F10="Partial",0.5,IF(F10="Fail",0,0))) | H10: Requires manual Switch Access / external keyboard testing. | I10: - | J10: =E10*G10 | K10: 'Keyboard' -> 'keyboard interface', which WCAG2ICT clarifies includes assistive technologies such as Switch Access/Full Keyboard Access that emulate key input, not only a physical keyboard. | L10: =IF(OR(F10="Pass",F10="Partial",F10="Fail"),1,0) | M10: No fix to prescribe yet - conduct the manual test first to confirm actual status.
A11: 2.4.3 | B11: Focus Order | C11: A | D11: Operable | E11: 3 | F11: Not Tested | G11: =IF(F11="Pass",1,IF(F11="Partial",0.5,IF(F11="Fail",0,0))) | H11: Requires manual TalkBack testing. | I11: - | J11: =E11*G11 | K11: Applies as written to the platform's own focus/accessibility-cursor order. | L11: =IF(OR(F11="Pass",F11="Partial",F11="Fail"),1,0) | M11: No fix to prescribe yet - conduct the manual test first to confirm actual status.
A12: 2.4.4 | B12: Link Purpose (In Context) | C12: A | D12: Operable | E12: 2 | F12: Fail | G12: =IF(F12="Pass",1,IF(F12="Partial",0.5,IF(F12="Fail",0,0))) | H12: Icon-only controls with no accessible purpose text: back / close, QR scanner, notifications, avatar, account '...' menu, carousel expand button. | I12: 45 | J12: =E12*G12 | K12: 'Link' -> any control that navigates or triggers an action (a quick-link icon, a list row); purpose must be determinable from its accessible name or surrounding context. | L12: =IF(OR(F12="Pass",F12="Partial",F12="Fail"),1,0) | M12: Give each icon-only control a name stating its action ('Back', 'Close', 'Scan QR code', 'Notifications', 'Profile', 'More account options').
A13: 2.5.1 | B13: Pointer Gestures | C13: A | D13: Operable | E13: 1 | F13: Pass | G13: =IF(F13="Pass",1,IF(F13="Partial",0.5,IF(F13="Fail",0,0))) | H13: Account-card carousel has a separate expand button (layoutExpandButton), so it is not swipe-only. No swipe-to-confirm or multi-point gestures observed. | I13: - | J13: =E13*G13 | K13: Applies as written; written with touch interfaces in mind from WCAG 2.1 onward. | L13: =IF(OR(F13="Pass",F13="Partial",F13="Fail"),1,0) | M13: No action needed on current evidence (the expand button still needs a label - see 1.1.1).
A14: 2.5.2 | B14: Pointer Cancellation | C14: A | D14: Operable | E14: 1 | F14: Not Tested | G14: =IF(F14="Pass",1,IF(F14="Partial",0.5,IF(F14="Fail",0,0))) | H14: Requires manual down-event/up-event testing. | I14: - | J14: =E14*G14 | K14: Applies as written to native touch handling (down-event vs up-event activation). | L14: =IF(OR(F14="Pass",F14="Partial",F14="Fail"),1,0) | M14: No fix to prescribe yet - conduct the manual test first to confirm actual status.
A15: 2.5.3 | B15: Label in Name | C15: A | D15: Operable | E15: 2 | F15: Partial | G15: =IF(F15="Pass",1,IF(F15="Partial",0.5,IF(F15="Fail",0,0))) | H15: Visible text not included in the accessible name: account-card text, 'View', the 'Currency' heading (screens 5, 6, 17). | I15: 4 | J15: =E15*G15 | K15: Applies as written: the programmatic accessible name must contain the visible label text so voice-control users can reference what they see. | L15: =IF(OR(F15="Pass",F15="Partial",F15="Fail"),1,0) | M15: Make sure the accessible name of the account card, 'View' shortcut and currency selector contains its visible text verbatim.
A16: 3.3.1 | B16: Error Identification | C16: A | D16: Understandable | E16: 3 | F16: Not Tested | G16: =IF(F16="Pass",1,IF(F16="Partial",0.5,IF(F16="Fail",0,0))) | H16: No inline field validation was triggered in the captured flows. The e-Kash limit dialog (20) and location-permission popup (1) are plain text, but whether they are announced was not confirmed. | I16: - | J16: =E16*G16 | K16: Applies as written; the error must be identified through the accessibility API (e.g. announced), not only shown visually. | L16: =IF(OR(F16="Pass",F16="Partial",F16="Fail"),1,0) | M16: No fix to prescribe yet - trigger validation errors (e.g. an invalid account number) with TalkBack on.
A17: 3.3.2 | B17: Labels or Instructions | C17: A | D17: Understandable | E17: 3 | F17: Fail | G17: =IF(F17="Pass",1,IF(F17="Partial",0.5,IF(F17="Fail",0,0))) | H17: The amount field has only the placeholder 'Enter an amount' (8, 12, 17, 19). The other-bank recipient 'Full name' and 'Account number' fields are placeholder-only (16). The e-Kash recipient field is a truncated placeholder only (21). Dropdowns do have persistent labels. | I17: 4 | J17: =E17*G17 | K17: Applies as written; WCAG2ICT notes placeholder-only text that disappears on input/focus is a common native-software failure mode of this criterion. | L17: =IF(OR(F17="Pass",F17="Partial",F17="Fail"),1,0) | M17: Give the amount, recipient full-name, account-number and e-Kash recipient fields persistent labels (floating-label pattern) that stay announced after typing starts.
A18: 3.3.9 | B18: Redundant Entry | C18: A | D18: Understandable | E18: 1 | F18: Not Tested | G18: =IF(F18="Pass",1,IF(F18="Partial",0.5,IF(F18="Fail",0,0))) | H18: Requires manual walkthrough. Positive signals: contact-book picker, recipient search, Favourites and Recents (14, 18, 21). All were empty for this test account. | I18: - | J18: =E18*G18 | K18: Applies as written; added in WCAG 2.2 with no web-specific terms. | L18: =IF(OR(F18="Pass",F18="Partial",F18="Fail"),1,0) | M18: No fix to prescribe yet - conduct the manual test first to confirm actual status.
A19: 1.3.5 | B19: Identify Input Purpose | C19: AA | D19: Perceivable | E19: 2 | F19: Not Tested | G19: =IF(F19="Pass",1,IF(F19="Partial",0.5,IF(F19="Fail",0,0))) | H19: Requires manual check: do fields like phone number / amount expose a standard input type so OS-level autofill can offer to complete them? | I19: - | J19: =E19*G19 | K19: 'Input purpose... can be programmatically determined' maps to using standard platform input types/autofill hints (e.g. Android autofillHints) rather than a generic text field. | L19: =IF(OR(F19="Pass",F19="Partial",F19="Fail"),1,0) | M19: No fix to prescribe yet - conduct the manual test first to confirm actual status.
A20: 3.2.1 | B20: On Focus | C20: A | D20: Operable | E20: 2 | F20: Not Tested | G20: =IF(F20="Pass",1,IF(F20="Partial",0.5,IF(F20="Fail",0,0))) | H20: Requires manual check: does simply moving focus onto a field (without activating it) ever trigger a navigation or submission? | I20: - | J20: =E20*G20 | K20: Applies as written; on native software this covers focus changes triggered by the accessibility cursor, not only literal keyboard focus. | L20: =IF(OR(F20="Pass",F20="Partial",F20="Fail"),1,0) | M20: No fix to prescribe yet - conduct the manual test first to confirm actual status.
A21: 3.2.2 | B21: On Input | C21: A | D21: Operable | E21: 2 | F21: Not Tested | G21: =IF(F21="Pass",1,IF(F21="Partial",0.5,IF(F21="Fail",0,0))) | H21: Requires manual check: does changing a field's value (e.g. selecting MTN vs Airtel) ever submit or navigate without an explicit confirm action? | I21: - | J21: =E21*G21 | K21: Applies as written; important on forms with toggles/selectors (network, Self/Other) that a screen-reader user changes one at a time. | L21: =IF(OR(F21="Pass",F21="Partial",F21="Fail"),1,0) | M21: No fix to prescribe yet - conduct the manual test first to confirm actual status.
A22: 4.1.2 | B22: Name, Role, Value | C22: A | D22: Robust | E22: 3 | F22: Fail | G22: =IF(F22="Pass",1,IF(F22="Partial",0.5,IF(F22="Fail",0,0))) | H22: 45 controls with no accessible name, plus 3 duplicate-description groups. The 6 bank radio buttons all announce 'not checked', 'Home' is duplicated, and 'Buy airtime' is duplicated. | I22: 48 | J22: =E22*G22 | K22: This is the core native-software criterion in WCAG2ICT: 'name, role, value' maps directly to what a platform accessibility API exposes for each control - exactly what Google Accessibility Scanner tests. | L22: =IF(OR(F22="Pass",F22="Partial",F22="Fail"),1,0) | M22: Fix the unlabelled controls (see 1.1.1). Give radio buttons a name plus a checked state. De-duplicate the 'Home' FAB / nav item and the two 'Buy airtime' actions so each has a distinct role and name.
A23: 1.4.3 | B23: Contrast (Minimum) | C23: AA | D23: Perceivable | E23: 1 | F23: Fail | G23: =IF(F23="Pass",1,IF(F23="Partial",0.5,IF(F23="Fail",0,0))) | H23: 12 text-contrast failures, lowest 1.04:1. Most sit on the dark-red account cards (#821A1A / #912422 on #8F201F) and on the account number (#413F3F on #333131). Disabled buttons ('Let me in', 'Continue', 'Submit') are low-contrast grey. Near misses: 4.44:1 login hint, 4.45:1 account name. | I23: 12 | J23: =E23*G23 | K23: Applies as written; 'text' includes native UI labels, not only web text. | L23: =IF(OR(F23="Pass",F23="Partial",F23="Fail"),1,0) | M23: Raise the text on the dark-red account cards and the grey account-number text to at least 4.5:1. The failing pairs are near-identical shades of the card colour, so this looks like a card-theming issue to fix at the style level.
A24: 1.4.4 | B24: Resize Text | C24: AA | D24: Perceivable | E24: 1 | F24: Partial | G24: =IF(F24="Pass",1,IF(F24="Partial",0.5,IF(F24="Fail",0,0))) | H24: Scanner flagged 69 fixed-height / fixed-width containers holding scalable text: 'Let me in', bottom navigation, balance and account cards, shortcut labels, Transact tiles, send button, bottom sheets. Clipping at 200% not yet confirmed visually. | I24: 69 | J24: =E24*G24 | K24: Applies with a platform-specific mechanism: resizing happens via the OS text-scale setting rather than browser zoom. | L24: =IF(OR(F24="Pass",F24="Partial",F24="Fail"),1,0) | M24: Change fixed LayoutParams to wrap_content / min-height on the flagged containers, then verify at 200% system font size.
A25: 1.4.10 | B25: Reflow | C25: AA | D25: Perceivable | E25: 1 | F25: Not Tested | G25: =IF(F25="Pass",1,IF(F25="Partial",0.5,IF(F25="Fail",0,0))) | H25: Requires manual OS font-scaling / zoom test. | I25: - | J25: =E25*G25 | K25: WCAG2ICT notes this applies where the software supports resizing/zoom; if the app has no zoom/scale feature at all, evaluate against the OS-level scaling it does support. | L25: =IF(OR(F25="Pass",F25="Partial",F25="Fail"),1,0) | M25: No fix to prescribe yet - conduct the manual test first to confirm actual status.
A26: 1.4.11 | B26: Non-text Contrast | C26: AA | D26: Perceivable | E26: 2 | F26: Fail | G26: =IF(F26="Pass",1,IF(F26="Partial",0.5,IF(F26="Fail",0,0))) | H26: 14 icon-contrast failures, all below 2:1 (lowest 1.01:1): the QR icon, the account '...' menu, the shortcut icons and the loading spinner against the dark-grey theme. | I26: 14 | J26: =E26*G26 | K26: Applies as written to native icons and UI component boundaries. | L26: =IF(OR(F26="Pass",F26="Partial",F26="Fail"),1,0) | M26: Lighten the icon foreground on the dark-grey (#3C3A3B-#444242) surfaces so every functional icon reaches 3:1.
A27: 2.4.6 | B27: Headings and Labels | C27: AA | D27: Operable | E27: 1 | F27: Pass | G27: =IF(F27="Pass",1,IF(F27="Partial",0.5,IF(F27="Fail",0,0))) | H27: Screen titles are descriptive ('Transact', 'Send to your own Equity account', 'Please select the recipient's bank', 'e-Kash limit'). | I27: - | J27: =E27*G27 | K27: 'Web page' -> 'screen/view'; each screen and section needs a descriptive, programmatically exposed title/heading. | L27: =IF(OR(F27="Pass",F27="Partial",F27="Fail"),1,0) | M27: No action needed on current evidence.
A28: 2.4.7 | B28: Focus Visible | C28: AA | D28: Operable | E28: 1 | F28: Not Tested | G28: =IF(F28="Pass",1,IF(F28="Partial",0.5,IF(F28="Fail",0,0))) | H28: Requires manual keyboard/switch focus-indicator testing. | I28: - | J28: =E28*G28 | K28: Applies where the platform supports a visible focus indicator (external keyboard, Switch Access, D-pad); not exercised by pure touch/screen-reader use, so needs manual testing on the relevant input mode. | L28: =IF(OR(F28="Pass",F28="Partial",F28="Fail"),1,0) | M28: No fix to prescribe yet - conduct the manual test first to confirm actual status.
A29: 2.5.8 | B29: Target Size (Minimum, 24x24px) | C29: AA | D29: Operable | E29: 2 | F29: Partial | G29: =IF(F29="Pass",1,IF(F29="Partial",0.5,IF(F29="Fail",0,0))) | H29: 45 targets flagged. 2 are below the 24dp WCAG floor: the 'Show balance' text (18dp) and the send-sheet close X. The rest are 24-43dp. | I29: 45 | J29: =E29*G29 | K29: Applies as written to native touch targets; note platform guidance (Android 48dp, Apple 44pt) is stricter than WCAG's own 24px floor - both are reported here. | L29: =IF(OR(F29="Pass",F29="Partial",F29="Fail"),1,0) | M29: Enlarge the 'Show balance' toggle and the send-sheet close X past 24dp (ideally 48dp).
A30: 3.2.4 | B30: Consistent Identification | C30: AA | D30: Understandable | E30: 0 | F30: N/A | G30: =IF(F30="Pass",1,IF(F30="Partial",0.5,IF(F30="Fail",0,0))) | H30: Excluded per Section 508 and EN 301 549, which both state (building on WCAG2ICT) that this criterion does not apply to non-web software. Retained here as a visible N/A rather than silently dropped. | I30: - | J30: =E30*G30 | K30: Explicitly excluded for non-web software by Section 508 and EN 301 549 - not scored. | L30: =IF(OR(F30="Pass",F30="Partial",F30="Fail"),1,0) | M30: Not applicable - excluded for non-web software.
